Workbook

Sheet Dashboard
A1: HR WORKFORCE ANALYTICS DASHBOARD
A4: TOTAL EMPLOYEES | D4: ATTRITION RATE | G4: AVG ANNUAL CTC | J4: AVG RATING | M4: AVG EXPERIENCE
A5: =KPI!B3 -> 1000 | D5: =KPI!B5 -> 0.176 | G5: =KPI!B7 -> 1073060 | J5: =KPI!B9 -> 3.58 | M5: =KPI!B10 -> 14.9
A9: FILTER BY DEPARTMENT: | D9: All
A10: Filtered Headcount | D10: =IF($D$9="All",KPI!B3,COUNTIF(Clean_Data!$H$2:$H$1001,$D$9)) -> 1000
A11: Filtered Avg Salary | D11: =IF($D$9="All",KPI!B6,ROUND(AVERAGEIF(Clean_Data!$H$2:$H$1001,$D$9,Clean_Data!$M$2:$M$1001),0)) -> 79452
A12: Filtered Attrition Rate | D12: =IF($D$9="All",KPI!B5,COUNTIFS(Clean_Data!$H$2:$H$1001,$D$9,Clean_Data!$Q$2:$Q$1001,"Yes")/COUNTIF(Clean_Data!$H$2:$H$1001,$D$9)) -> 0.176

Sheet Raw_Data
A1: Employee_ID | B1: Join_Date | C1: Employee_Name | D1: Gender | E1: Age | F1: State | G1: City | H1: Department | I1: Designation_Level | J1: Designation_Title | K1: Experience_Years | L1: Employment_Type | M1: Monthly_Salary | N1: Annual_CTC | O1: Bonus_Amount | P1: Performance_Rating | Q1: Attrition | R1: Leaves_Taken | S1: Overtime_Hours | T1: Manager_Name | U1: Education | V1: Marital_Status
A2: EMP0001 | B2: 45669 | C2: Yash Mehta | D2: Male | E2: 29 | F2: Tamil Nadu | G2: Chennai | H2: Sales | I2: Executive | J2: Key Account Manager | K2: 10 | L2: Part-Time | M2: 38100 | N2: 530352 | O2: 73152 | P2: 1 | Q2: No | R2: 11 | S2: 29 | T2: Ritu Chawla | U2: Bachelor's | V2: Married
A3: EMP0002 | B3: 45939 | C3: Neha Bansal | D3: Female | E3: 48 | F3: Karnataka | G3: Bengaluru | H3: Sales | I3: Director | J3: Key Account Manager | K3: 11 | L3: Full-Time | M3: 228200 | N3: 2902704 | O3: 164304 | P3: 4 | Q3: No | R3: 6 | S3: 17 | T3: Deepa Krishnan | U3: Diploma | V3: Married
A4: EMP0003 | B4: 45761 | C4: Vivaan Menon | D4: Male | E4: 49 | F4: Telangana | G4: Hyderabad | H4: HR | I4: Senior Manager | J4: HR Manager | K4: 13 | L4: Full-Time | M4: 110300 | N4: 1535376 | O4: 211776 | P4: 3 | Q4: No | R4: 3 | S4: 28 | T4: Sunita Rao | U4: Master's | V4: Married
A5: EMP0004 | B5: 45669 | C5: Kritika Singh | D5: Female | E5: 35 | F5: Telangana | G5: Hyderabad | H5: Engineering | I5: Director | J5: Tech Lead | K5: 15 | L5: Full-Time | M5: 257400 | N5: 3521232 | O5: 432432 | P5: 5 | Q5: No | R5: 12 | S5: 40 | T5: Rajesh Khanna | U5: Bachelor's | V5: Single
A6: EMP0005 | B6: 45835 | C6: Kabir Pillai | D6: Male | E6: 38 | F6: Rajasthan | G6: Jaipur | H6: Finance | I6: Manager | J6: CFO Office | K6: 9 | L6: Full-Time | M6: 82200 | N6: 1163952 | O6: 177552 | P6: 4 | Q6: No | R6: 15 | S6: 22 | T6: Kavita Menon | U6: Master's | V6: Married
A7: EMP0006 | B7: 45965 | C7: Diya Reddy | D7: Female | E7: 35 | F7: Uttar Pradesh | G7: Lucknow | H7: Finance | I7: Senior Executive | J7: Finance Controller | K7: 8 | L7: Full-Time | M7: 53100 | N7: 713664 | O7: 76464 | P7: 3 | Q7: No | R7: 16 | S7: 31 | T7: Deepa Krishnan | U7: Diploma | V7: Single
A8: EMP0007 | B8: 45760 | C8: Pari Pillai | D8: Female | E8: 43 | F8: Gujarat | G8: Ahmedabad | H8: HR | I8: Executive | J8: HR Director | K8: 5 | L8: Full-Time | M8: 30100 | N8: 400932 | O8: 39732 | P8: 5 | Q8: No | R8: 6 | S8: 32 | T8: Rajesh Khanna | U8: Bachelor's | V8: Single
A9: EMP0008 | B9: 45681 | C9: Pari Nair | D9: Female | E9: 29 | F9: West Bengal | G9: Kolkata | H9: Engineering | I9: Manager | J9: Senior Software Engineer | K9: 11 | L9: Full-Time | M9: 89600 | N9: 1161216 | O9: 86016 | P9: 4 | Q9: No | R9: 16 | S9: 11 | T9: Sandeep Bhatia | U9: Master's | V9: Single
A10: EMP0009 | B10: 45830 | C10: Amit Verma | D10: Male | E10: 23 | F10: Madhya Pradesh | G10: Bhopal | H10: Sales | I10: Senior Executive | J10: Sales Executive | K10: 18 | L10: Full-Time | M10: 58400 | N10: 784896 | O10: 84096 | P10: 4 | Q10: No | R10: 10 | S10: 16 | T10: Ritu Chawla | U10: Bachelor's | V10: Married
A11: EMP0010 | B11: 45870 | C11: Rahul Agarwal | D11: Male | E11: 54 | F11: West Bengal | G11: Kolkata | H11: Engineering | I11: Executive | J11: Tech Lead | K11: 2 | L11: Full-Time | M11: 45100 | N11: 568260 | O11: 27060 | P11: 4 | Q11: No | R11: 6 | S11: 40 | T11: Rajesh Khanna | U11: Bachelor's | V11: Married
A12: EMP0011 | B12: 45771 | C12: Tanvi Rao | D12: Female | E12: 56 | F12: Telangana | G12: Hyderabad | H12: HR | I12: Manager | J12: HR Executive | K12: 19 | L12: Full-Time | M12: 74000 | N12: 941280 | O12: 53280 | P12: 5 | Q12: No | R12: 8 | S12: 40 | T12: Alok Mehra | U12: Master's | V12: Married
A13: EMP0012 | B13: 45748 | C13: Aarav Menon | D13: Male | E13: 32 | F13: Maharashtra | G13: Mumbai | H13: Sales | I13: Senior Manager | J13: Sales Director | K13: 29 | L13: Full-Time | M13: 115700 | N13: 1596659 | O13: 208260 | P13: 1 | Q13: No | R13: 17 | S13: 1 | T13: Ritu Chawla | U13: Bachelor's | V13: Married
... A1001: EMP1000 | B1001: 45913 | C1001: Saanvi Sharma | D1001: Female | E1001: 36 | F1001: Uttar Pradesh | G1001: Lucknow | H1001: Engineering | I1001: Senior Executive | J1001: Tech Lead | K1001: 7 | L1001: Full-Time | M1001: 75800 | N1001: 1073328 | O1001: 163728 | P1001: 3 | Q1001: No | R1001: 1 | S1001: 7 | T1001: Ritu Chawla | U1001: Master's | V1001: Single

Sheet Clean_Data
A1: Employee_ID | B1: Join_Date | C1: Employee_Name | D1: Gender | E1: Age | F1: State | G1: City | H1: Department | I1: Designation_Level | J1: Designation_Title | K1: Experience_Years | L1: Employment_Type | M1: Monthly_Salary | N1: Annual_CTC | O1: Bonus_Amount | P1: Performance_Rating | Q1: Attrition | R1: Leaves_Taken | S1: Overtime_Hours | T1: Manager_Name | U1: Education | V1: Marital_Status | W1: Age_Group | X1: Experience_Band | Y1: Join_Month | Z1: Join_Year | AA1: Attrition_Flag
A2: EMP0001 | B2: 45669 | C2: Yash Mehta | D2: Male | E2: 29 | F2: Tamil Nadu | G2: Chennai | H2: Sales | I2: Executive | J2: Key Account Manager | K2: 10 | L2: Part-Time | M2: 38100 | N2: 530352 | O2: 73152 | P2: 1 | Q2: No | R2: 11 | S2: 29 | T2: Ritu Chawla | U2: Bachelor's | V2: Married | W2: =IF(E2<=30,"22-30",IF(E2<=40,"31-40",IF(E2<=50,"41-50","51-58"))) -> 22-30 | X2: =IF(K2<=5,"0-5 yrs",IF(K2<=10,"6-10 yrs",IF(K2<=20,"11-20 yrs","21-30 yrs"))) -> 6-10 yrs | Y2: =TEXT(B2,"mmm") -> Jan | Z2: =YEAR(B2) -> 2025 | AA2: =IF(Q2="Yes",1,0) -> 0
A3: EMP0002 | B3: 45939 | C3: Neha Bansal | D3: Female | E3: 48 | F3: Karnataka | G3: Bengaluru | H3: Sales | I3: Director | J3: Key Account Manager | K3: 11 | L3: Full-Time | M3: 228200 | N3: 2902704 | O3: 164304 | P3: 4 | Q3: No | R3: 6 | S3: 17 | T3: Deepa Krishnan | U3: Diploma | V3: Married | W3: =IF(E3<=30,"22-30",IF(E3<=40,"31-40",IF(E3<=50,"41-50","51-58"))) -> 41-50 | X3: =IF(K3<=5,"0-5 yrs",IF(K3<=10,"6-10 yrs",IF(K3<=20,"11-20 yrs","21-30 yrs"))) -> 11-20 yrs | Y3: =TEXT(B3,"mmm") -> Oct | Z3: =YEAR(B3) -> 2025 | AA3: =IF(Q3="Yes",1,0) -> 0
A4: EMP0003 | B4: 45761 | C4: Vivaan Menon | D4: Male | E4: 49 | F4: Telangana | G4: Hyderabad | H4: HR | I4: Senior Manager | J4: HR Manager | K4: 13 | L4: Full-Time | M4: 110300 | N4: 1535376 | O4: 211776 | P4: 3 | Q4: No | R4: 3 | S4: 28 | T4: Sunita Rao | U4: Master's | V4: Married | W4: =IF(E4<=30,"22-30",IF(E4<=40,"31-40",IF(E4<=50,"41-50","51-58"))) -> 41-50 | X4: =IF(K4<=5,"0-5 yrs",IF(K4<=10,"6-10 yrs",IF(K4<=20,"11-20 yrs","21-30 yrs"))) -> 11-20 yrs | Y4: =TEXT(B4,"mmm") -> Apr | Z4: =YEAR(B4) -> 2025 | AA4: =IF(Q4="Yes",1,0) -> 0
A5: EMP0004 | B5: 45669 | C5: Kritika Singh | D5: Female | E5: 35 | F5: Telangana | G5: Hyderabad | H5: Engineering | I5: Director | J5: Tech Lead | K5: 15 | L5: Full-Time | M5: 257400 | N5: 3521232 | O5: 432432 | P5: 5 | Q5: No | R5: 12 | S5: 40 | T5: Rajesh Khanna | U5: Bachelor's | V5: Single | W5: =IF(E5<=30,"22-30",IF(E5<=40,"31-40",IF(E5<=50,"41-50","51-58"))) -> 31-40 | X5: =IF(K5<=5,"0-5 yrs",IF(K5<=10,"6-10 yrs",IF(K5<=20,"11-20 yrs","21-30 yrs"))) -> 11-20 yrs | Y5: =TEXT(B5,"mmm") -> Jan | Z5: =YEAR(B5) -> 2025 | AA5: =IF(Q5="Yes",1,0) -> 0
A6: EMP0005 | B6: 45835 | C6: Kabir Pillai | D6: Male | E6: 38 | F6: Rajasthan | G6: Jaipur | H6: Finance | I6: Manager | J6: CFO Office | K6: 9 | L6: Full-Time | M6: 82200 | N6: 1163952 | O6: 177552 | P6: 4 | Q6: No | R6: 15 | S6: 22 | T6: Kavita Menon | U6: Master's | V6: Married | W6: =IF(E6<=30,"22-30",IF(E6<=40,"31-40",IF(E6<=50,"41-50","51-58"))) -> 31-40 | X6: =IF(K6<=5,"0-5 yrs",IF(K6<=10,"6-10 yrs",IF(K6<=20,"11-20 yrs","21-30 yrs"))) -> 6-10 yrs | Y6: =TEXT(B6,"mmm") -> Jun | Z6: =YEAR(B6) -> 2025 | AA6: =IF(Q6="Yes",1,0) -> 0
A7: EMP0006 | B7: 45965 | C7: Diya Reddy | D7: Female | E7: 35 | F7: Uttar Pradesh | G7: Lucknow | H7: Finance | I7: Senior Executive | J7: Finance Controller | K7: 8 | L7: Full-Time | M7: 53100 | N7: 713664 | O7: 76464 | P7: 3 | Q7: No | R7: 16 | S7: 31 | T7: Deepa Krishnan | U7: Diploma | V7: Single | W7: =IF(E7<=30,"22-30",IF(E7<=40,"31-40",IF(E7<=50,"41-50","51-58"))) -> 31-40 | X7: =IF(K7<=5,"0-5 yrs",IF(K7<=10,"6-10 yrs",IF(K7<=20,"11-20 yrs","21-30 yrs"))) -> 6-10 yrs | Y7: =TEXT(B7,"mmm") -> Nov | Z7: =YEAR(B7) -> 2025 | AA7: =IF(Q7="Yes",1,0) -> 0
A8: EMP0007 | B8: 45760 | C8: Pari Pillai | D8: Female | E8: 43 | F8: Gujarat | G8: Ahmedabad | H8: HR | I8: Executive | J8: HR Director | K8: 5 | L8: Full-Time | M8: 30100 | N8: 400932 | O8: 39732 | P8: 5 | Q8: No | R8: 6 | S8: 32 | T8: Rajesh Khanna | U8: Bachelor's | V8: Single | W8: =IF(E8<=30,"22-30",IF(E8<=40,"31-40",IF(E8<=50,"41-50","51-58"))) -> 41-50 | X8: =IF(K8<=5,"0-5 yrs",IF(K8<=10,"6-10 yrs",IF(K8<=20,"11-20 yrs","21-30 yrs"))) -> 0-5 yrs | Y8: =TEXT(B8,"mmm") -> Apr | Z8: =YEAR(B8) -> 2025 | AA8: =IF(Q8="Yes",1,0) -> 0
A9: EMP0008 | B9: 45681 | C9: Pari Nair | D9: Female | E9: 29 | F9: West Bengal | G9: Kolkata | H9: Engineering | I9: Manager | J9: Senior Software Engineer | K9: 11 | L9: Full-Time | M9: 89600 | N9: 1161216 | O9: 86016 | P9: 4 | Q9: No | R9: 16 | S9: 11 | T9: Sandeep Bhatia | U9: Master's | V9: Single | W9: =IF(E9<=30,"22-30",IF(E9<=40,"31-40",IF(E9<=50,"41-50","51-58"))) -> 22-30 | X9: =IF(K9<=5,"0-5 yrs",IF(K9<=10,"6-10 yrs",IF(K9<=20,"11-20 yrs","21-30 yrs"))) -> 11-20 yrs | Y9: =TEXT(B9,"mmm") -> Jan | Z9: =YEAR(B9) -> 2025 | AA9: =IF(Q9="Yes",1,0) -> 0
A10: EMP0009 | B10: 45830 | C10: Amit Verma | D10: Male | E10: 23 | F10: Madhya Pradesh | G10: Bhopal | H10: Sales | I10: Senior Executive | J10: Sales Executive | K10: 18 | L10: Full-Time | M10: 58400 | N10: 784896 | O10: 84096 | P10: 4 | Q10: No | R10: 10 | S10: 16 | T10: Ritu Chawla | U10: Bachelor's | V10: Married | W10: =IF(E10<=30,"22-30",IF(E10<=40,"31-40",IF(E10<=50,"41-50","51-58"))) -> 22-30 | X10: =IF(K10<=5,"0-5 yrs",IF(K10<=10,"6-10 yrs",IF(K10<=20,"11-20 yrs","21-30 yrs"))) -> 11-20 yrs | Y10: =TEXT(B10,"mmm") -> Jun | Z10: =YEAR(B10) -> 2025 | AA10: =IF(Q10="Yes",1,0) -> 0
A11: EMP0010 | B11: 45870 | C11: Rahul Agarwal | D11: Male | E11: 54 | F11: West Bengal | G11: Kolkata | H11: Engineering | I11: Executive | J11: Tech Lead | K11: 2 | L11: Full-Time | M11: 45100 | N11: 568260 | O11: 27060 | P11: 4 | Q11: No | R11: 6 | S11: 40 | T11: Rajesh Khanna | U11: Bachelor's | V11: Married | W11: =IF(E11<=30,"22-30",IF(E11<=40,"31-40",IF(E11<=50,"41-50","51-58"))) -> 51-58 | X11: =IF(K11<=5,"0-5 yrs",IF(K11<=10,"6-10 yrs",IF(K11<=20,"11-20 yrs","21-30 yrs"))) -> 0-5 yrs | Y11: =TEXT(B11,"mmm") -> Aug | Z11: =YEAR(B11) -> 2025 | AA11: =IF(Q11="Yes",1,0) -> 0
A12: EMP0011 | B12: 45771 | C12: Tanvi Rao | D12: Female | E12: 56 | F12: Telangana | G12: Hyderabad | H12: HR | I12: Manager | J12: HR Executive | K12: 19 | L12: Full-Time | M12: 74000 | N12: 941280 | O12: 53280 | P12: 5 | Q12: No | R12: 8 | S12: 40 | T12: Alok Mehra | U12: Master's | V12: Married | W12: =IF(E12<=30,"22-30",IF(E12<=40,"31-40",IF(E12<=50,"41-50","51-58"))) -> 51-58 | X12: =IF(K12<=5,"0-5 yrs",IF(K12<=10,"6-10 yrs",IF(K12<=20,"11-20 yrs","21-30 yrs"))) -> 11-20 yrs | Y12: =TEXT(B12,"mmm") -> Apr | Z12: =YEAR(B12) -> 2025 | AA12: =IF(Q12="Yes",1,0) -> 0
A13: EMP0012 | B13: 45748 | C13: Aarav Menon | D13: Male | E13: 32 | F13: Maharashtra | G13: Mumbai | H13: Sales | I13: Senior Manager | J13: Sales Director | K13: 29 | L13: Full-Time | M13: 115700 | N13: 1596659 | O13: 208260 | P13: 1 | Q13: No | R13: 17 | S13: 1 | T13: Ritu Chawla | U13: Bachelor's | V13: Married | W13: =IF(E13<=30,"22-30",IF(E13<=40,"31-40",IF(E13<=50,"41-50","51-58"))) -> 31-40 | X13: =IF(K13<=5,"0-5 yrs",IF(K13<=10,"6-10 yrs",IF(K13<=20,"11-20 yrs","21-30 yrs"))) -> 21-30 yrs | Y13: =TEXT(B13,"mmm") -> Apr | Z13: =YEAR(B13) -> 2025 | AA13: =IF(Q13="Yes",1,0) -> 0
... A1001: EMP1000 | B1001: 45913 | C1001: Saanvi Sharma | D1001: Female | E1001: 36 | F1001: Uttar Pradesh | G1001: Lucknow | H1001: Engineering | I1001: Senior Executive | J1001: Tech Lead | K1001: 7 | L1001: Full-Time | M1001: 75800 | N1001: 1073328 | O1001: 163728 | P1001: 3 | Q1001: No | R1001: 1 | S1001: 7 | T1001: Ritu Chawla | U1001: Master's | V1001: Single | W1001: =IF(E1001<=30,"22-30",IF(E1001<=40,"31-40",IF(E1001<=50,"41-50","51-58"))) -> 31-40 | X1001: =IF(K1001<=5,"0-5 yrs",IF(K1001<=10,"6-10 yrs",IF(K1001<=20,"11-20 yrs","21-30 yrs"))) -> 6-10 yrs | Y1001: =TEXT(B1001,"mmm") -> Sep | Z1001: =YEAR(B1001) -> 2025 | AA1001: =IF(Q1001="Yes",1,0) -> 0

Sheet KPI
A1: HR WORKFORCE — HEADLINE KPIs
A3: Total Employees | B3: =COUNTA(Clean_Data!$A$2:$A$1001) -> 1000
A4: Total Attrition | B4: =COUNTIF(Clean_Data!$Q$2:$Q$1001,"Yes") -> 176
A5: Attrition Rate | B5: =B4/B3 -> 0.176
A6: Avg Monthly Salary | B6: =ROUND(AVERAGE(Clean_Data!$M$2:$M$1001),0) -> 79452
A7: Avg Annual CTC | B7: =ROUND(AVERAGE(Clean_Data!$N$2:$N$1001),0) -> 1073060
A8: Avg Age | B8: =ROUND(AVERAGE(Clean_Data!$E$2:$E$1001),1) -> 40.2
A9: Avg Performance Rating | B9: =ROUND(AVERAGE(Clean_Data!$P$2:$P$1001),2) -> 3.58
A10: Avg Experience (yrs) | B10: =ROUND(AVERAGE(Clean_Data!$K$2:$K$1001),1) -> 14.9
A11: Avg Leaves Taken | B11: =ROUND(AVERAGE(Clean_Data!$R$2:$R$1001),1) -> 10.2
A12: Avg Overtime Hours | B12: =ROUND(AVERAGE(Clean_Data!$S$2:$S$1001),1) -> 20.3

Sheet Pivot
A1: 1. DEPARTMENT-WISE SUMMARY | F1: 8. AGE GROUP SUMMARY
A2: Department | B2: Headcount | C2: Avg Annual CTC | D2: Avg Rating | F2: Age Group | G2: Headcount | H2: Avg Salary
A3: Engineering | B3: =COUNTIF(Clean_Data!$H$2:$H$1001,A3) -> 294 | C3: =ROUND(AVERAGEIF(Clean_Data!$H$2:$H$1001,A3,Clean_Data!$N$2:$N$1001),0) -> 1153045 | D3: =ROUND(AVERAGEIF(Clean_Data!$H$2:$H$1001,A3,Clean_Data!$P$2:$P$1001),2) -> 3.59 | F3: 22-30 | G3: =COUNTIF(Clean_Data!$W$2:$W$1001,F3) -> 232 | H3: =ROUND(AVERAGEIF(Clean_Data!$W$2:$W$1001,F3,Clean_Data!$M$2:$M$1001),0) -> 81815
A4: Finance | B4: =COUNTIF(Clean_Data!$H$2:$H$1001,A4) -> 148 | C4: =ROUND(AVERAGEIF(Clean_Data!$H$2:$H$1001,A4,Clean_Data!$N$2:$N$1001),0) -> 1208510 | D4: =ROUND(AVERAGEIF(Clean_Data!$H$2:$H$1001,A4,Clean_Data!$P$2:$P$1001),2) -> 3.64 | F4: 31-40 | G4: =COUNTIF(Clean_Data!$W$2:$W$1001,F4) -> 276 | H4: =ROUND(AVERAGEIF(Clean_Data!$W$2:$W$1001,F4,Clean_Data!$M$2:$M$1001),0) -> 78758
A5: HR | B5: =COUNTIF(Clean_Data!$H$2:$H$1001,A5) -> 133 | C5: =ROUND(AVERAGEIF(Clean_Data!$H$2:$H$1001,A5,Clean_Data!$N$2:$N$1001),0) -> 918264 | D5: =ROUND(AVERAGEIF(Clean_Data!$H$2:$H$1001,A5,Clean_Data!$P$2:$P$1001),2) -> 3.52 | F5: 41-50 | G5: =COUNTIF(Clean_Data!$W$2:$W$1001,F5) -> 264 | H5: =ROUND(AVERAGEIF(Clean_Data!$W$2:$W$1001,F5,Clean_Data!$M$2:$M$1001),0) -> 79072
A6: Operations | B6: =COUNTIF(Clean_Data!$H$2:$H$1001,A6) -> 153 | C6: =ROUND(AVERAGEIF(Clean_Data!$H$2:$H$1001,A6,Clean_Data!$N$2:$N$1001),0) -> 1034516 | D6: =ROUND(AVERAGEIF(Clean_Data!$H$2:$H$1001,A6,Clean_Data!$P$2:$P$1001),2) -> 3.68 | F6: 51-58 | G6: =COUNTIF(Clean_Data!$W$2:$W$1001,F6) -> 228 | H6: =ROUND(AVERAGEIF(Clean_Data!$W$2:$W$1001,F6,Clean_Data!$M$2:$M$1001),0) -> 78325
A7: Sales | B7: =COUNTIF(Clean_Data!$H$2:$H$1001,A7) -> 272 | C7: =ROUND(AVERAGEIF(Clean_Data!$H$2:$H$1001,A7,Clean_Data!$N$2:$N$1001),0) -> 1010277 | D7: =ROUND(AVERAGEIF(Clean_Data!$H$2:$H$1001,A7,Clean_Data!$P$2:$P$1001),2) -> 3.53
F8: 9. EXPERIENCE BAND SUMMARY
A9: 2. STATE-WISE HEADCOUNT | F9: Experience Band | G9: Headcount | H9: Avg Salary
A10: State | B10: Headcount | F10: 0-5 yrs | G10: =COUNTIF(Clean_Data!$X$2:$X$1001,F10) -> 181 | H10: =ROUND(AVERAGEIF(Clean_Data!$X$2:$X$1001,F10,Clean_Data!$M$2:$M$1001),0) -> 77047
A11: Delhi | B11: =COUNTIF(Clean_Data!$F$2:$F$1001,A11) -> 98 | F11: 6-10 yrs | G11: =COUNTIF(Clean_Data!$X$2:$X$1001,F11) -> 164 | H11: =ROUND(AVERAGEIF(Clean_Data!$X$2:$X$1001,F11,Clean_Data!$M$2:$M$1001),0) -> 77623
A12: Gujarat | B12: =COUNTIF(Clean_Data!$F$2:$F$1001,A12) -> 106 | F12: 11-20 yrs | G12: =COUNTIF(Clean_Data!$X$2:$X$1001,F12) -> 348 | H12: =ROUND(AVERAGEIF(Clean_Data!$X$2:$X$1001,F12,Clean_Data!$M$2:$M$1001),0) -> 80660
A13: Karnataka | B13: =COUNTIF(Clean_Data!$F$2:$F$1001,A13) -> 97 | F13: 21-30 yrs | G13: =COUNTIF(Clean_Data!$X$2:$X$1001,F13) -> 307 | H13: =ROUND(AVERAGEIF(Clean_Data!$X$2:$X$1001,F13,Clean_Data!$M$2:$M$1001),0) -> 80476
A14: Madhya Pradesh | B14: =COUNTIF(Clean_Data!$F$2:$F$1001,A14) -> 104
A15: Maharashtra | B15: =COUNTIF(Clean_Data!$F$2:$F$1001,A15) -> 108 | F15: 10. ATTRITED vs RETAINED
A16: Rajasthan | B16: =COUNTIF(Clean_Data!$F$2:$F$1001,A16) -> 107 | F16: Status | G16: Headcount | H16: Avg Rating | I16: Avg Leaves | J16: Avg Overtime
A17: Tamil Nadu | B17: =COUNTIF(Clean_Data!$F$2:$F$1001,A17) -> 99 | F17: Attrited | G17: =COUNTIF(Clean_Data!$Q$2:$Q$1001,"Yes") -> 176 | H17: =ROUND(AVERAGEIF(Clean_Data!$Q$2:$Q$1001,"Yes",Clean_Data!$P$2:$P$1001),2) -> 3.51 | I17: =ROUND(AVERAGEIF(Clean_Data!$Q$2:$Q$1001,"Yes",Clean_Data!$R$2:$R$1001),1) -> 9.9 | J17: =ROUND(AVERAGEIF(Clean_Data!$Q$2:$Q$1001,"Yes",Clean_Data!$S$2:$S$1001),1) -> 20.3
A18: Telangana | B18: =COUNTIF(Clean_Data!$F$2:$F$1001,A18) -> 86 | F18: Retained | G18: =COUNTIF(Clean_Data!$Q$2:$Q$1001,"No") -> 824 | H18: =ROUND(AVERAGEIF(Clean_Data!$Q$2:$Q$1001,"No",Clean_Data!$P$2:$P$1001),2) -> 3.6 | I18: =ROUND(AVERAGEIF(Clean_Data!$Q$2:$Q$1001,"No",Clean_Data!$R$2:$R$1001),1) -> 10.2 | J18: =ROUND(AVERAGEIF(Clean_Data!$Q$2:$Q$1001,"No",Clean_Data!$S$2:$S$1001),1) -> 20.3
A19: Uttar Pradesh | B19: =COUNTIF(Clean_Data!$F$2:$F$1001,A19) -> 92
A20: West Bengal | B20: =COUNTIF(Clean_Data!$F$2:$F$1001,A20) -> 103 | F20: 11. MANAGER-WISE TEAM SIZE (RANKED)
F21: Manager | G21: Team Size | H21: Avg Rating | I21: Rank
A22: 3. DESIGNATION LEVEL — AVG SALARY | F22: Alok Mehra | G22: =COUNTIF(Clean_Data!$T$2:$T$1001,F22) -> 89 | H22: =ROUND(AVERAGEIF(Clean_Data!$T$2:$T$1001,F22,Clean_Data!$P$2:$P$1001),2) -> 3.46 | I22: =RANK(G22,$G$22:$G$31) -> 10
A23: Designation Level | B23: Headcount | C23: Avg Monthly Salary | F23: Anil Saxena | G23: =COUNTIF(Clean_Data!$T$2:$T$1001,F23) -> 93 | H23: =ROUND(AVERAGEIF(Clean_Data!$T$2:$T$1001,F23,Clean_Data!$P$2:$P$1001),2) -> 3.76 | I23: =RANK(G23,$G$22:$G$31) -> 9
A24: Director | B24: =COUNTIF(Clean_Data!$I$2:$I$1001,A24) -> 67 | C24: =ROUND(AVERAGEIF(Clean_Data!$I$2:$I$1001,A24,Clean_Data!$M$2:$M$1001),0) -> 222957 | F24: Deepa Krishnan | G24: =COUNTIF(Clean_Data!$T$2:$T$1001,F24) -> 102 | H24: =ROUND(AVERAGEIF(Clean_Data!$T$2:$T$1001,F24,Clean_Data!$P$2:$P$1001),2) -> 3.6 | I24: =RANK(G24,$G$22:$G$31) -> 5
A25: Senior Manager | B25: =COUNTIF(Clean_Data!$I$2:$I$1001,A25) -> 111 | C25: =ROUND(AVERAGEIF(Clean_Data!$I$2:$I$1001,A25,Clean_Data!$M$2:$M$1001),0) -> 139088 | F25: Kavita Menon | G25: =COUNTIF(Clean_Data!$T$2:$T$1001,F25) -> 101 | H25: =ROUND(AVERAGEIF(Clean_Data!$T$2:$T$1001,F25,Clean_Data!$P$2:$P$1001),2) -> 3.68 | I25: =RANK(G25,$G$22:$G$31) -> 6
A26: Manager | B26: =COUNTIF(Clean_Data!$I$2:$I$1001,A26) -> 211 | C26: =ROUND(AVERAGEIF(Clean_Data!$I$2:$I$1001,A26,Clean_Data!$M$2:$M$1001),0) -> 91411 | F26: Manoj Tiwari | G26: =COUNTIF(Clean_Data!$T$2:$T$1001,F26) -> 95 | H26: =ROUND(AVERAGEIF(Clean_Data!$T$2:$T$1001,F26,Clean_Data!$P$2:$P$1001),2) -> 3.52 | I26: =RANK(G26,$G$22:$G$31) -> 8
A27: Senior Executive | B27: =COUNTIF(Clean_Data!$I$2:$I$1001,A27) -> 296 | C27: =ROUND(AVERAGEIF(Clean_Data!$I$2:$I$1001,A27,Clean_Data!$M$2:$M$1001),0) -> 60463 | F27: Preeti Shah | G27: =COUNTIF(Clean_Data!$T$2:$T$1001,F27) -> 96 | H27: =ROUND(AVERAGEIF(Clean_Data!$T$2:$T$1001,F27,Clean_Data!$P$2:$P$1001),2) -> 3.76 | I27: =RANK(G27,$G$22:$G$31) -> 7
A28: Executive | B28: =COUNTIF(Clean_Data!$I$2:$I$1001,A28) -> 315 | C28: =ROUND(AVERAGEIF(Clean_Data!$I$2:$I$1001,A28,Clean_Data!$M$2:$M$1001),0) -> 37745 | F28: Rajesh Khanna | G28: =COUNTIF(Clean_Data!$T$2:$T$1001,F28) -> 106 | H28: =ROUND(AVERAGEIF(Clean_Data!$T$2:$T$1001,F28,Clean_Data!$P$2:$P$1001),2) -> 3.58 | I28: =RANK(G28,$G$22:$G$31) -> 2
F29: Ritu Chawla | G29: =COUNTIF(Clean_Data!$T$2:$T$1001,F29) -> 108 | H29: =ROUND(AVERAGEIF(Clean_Data!$T$2:$T$1001,F29,Clean_Data!$P$2:$P$1001),2) -> 3.47 | I29: =RANK(G29,$G$22:$G$31) -> 1
A30: 4. EMPLOYMENT TYPE SPLIT | F30: Sandeep Bhatia | G30: =COUNTIF(Clean_Data!$T$2:$T$1001,F30) -> 104 | H30: =ROUND(AVERAGEIF(Clean_Data!$T$2:$T$1001,F30,Clean_Data!$P$2:$P$1001),2) -> 3.5 | I30: =RANK(G30,$G$22:$G$31) -> 4
A31: Employment Type | B31: Headcount | C31: % of Total | F31: Sunita Rao | G31: =COUNTIF(Clean_Data!$T$2:$T$1001,F31) -> 106 | H31: =ROUND(AVERAGEIF(Clean_Data!$T$2:$T$1001,F31,Clean_Data!$P$2:$P$1001),2) -> 3.52 | I31: =RANK(G31,$G$22:$G$31) -> 2
A32: Full-Time | B32: =COUNTIF(Clean_Data!$L$2:$L$1001,A32) -> 822 | C32: =B32/$B$3 -> 2.7959184
A33: Part-Time | B33: =COUNTIF(Clean_Data!$L$2:$L$1001,A33) -> 102 | C33: =B33/$B$3 -> 0.34693878
A34: Contract | B34: =COUNTIF(Clean_Data!$L$2:$L$1001,A34) -> 76 | C34: =B34/$B$3 -> 0.2585034
A36: 5. GENDER PAY COMPARISON
A37: Gender | B37: Headcount | C37: Avg Salary | D37: Avg Rating
A38: Male | B38: =COUNTIF(Clean_Data!$D$2:$D$1001,A38) -> 579 | C38: =ROUND(AVERAGEIF(Clean_Data!$D$2:$D$1001,A38,Clean_Data!$M$2:$M$1001),0) -> 78784 | D38: =ROUND(AVERAGEIF(Clean_Data!$D$2:$D$1001,A38,Clean_Data!$P$2:$P$1001),2) -> 3.59
A39: Female | B39: =COUNTIF(Clean_Data!$D$2:$D$1001,A39) -> 421 | C39: =ROUND(AVERAGEIF(Clean_Data!$D$2:$D$1001,A39,Clean_Data!$M$2:$M$1001),0) -> 80369 | D39: =ROUND(AVERAGEIF(Clean_Data!$D$2:$D$1001,A39,Clean_Data!$P$2:$P$1001),2) -> 3.57
A41: 6. ATTRITION BY DEPARTMENT
A42: Department | B42: Attrition Count | C42: Headcount | D42: Attrition Rate
...

Sheet Calculation
A1: A. MONTHLY NEW-HIRE TREND (2025)
A2: Month | B2: New Hires | C2: Avg Starting Salary
A3: Jan | B3: =COUNTIF(Clean_Data!$Y$2:$Y$1001,A3) -> 67 | C3: =ROUND(AVERAGEIF(Clean_Data!$Y$2:$Y$1001,A3,Clean_Data!$M$2:$M$1001),0) -> 81103
A4: Feb | B4: =COUNTIF(Clean_Data!$Y$2:$Y$1001,A4) -> 100 | C4: =ROUND(AVERAGEIF(Clean_Data!$Y$2:$Y$1001,A4,Clean_Data!$M$2:$M$1001),0) -> 77918
A5: Mar | B5: =COUNTIF(Clean_Data!$Y$2:$Y$1001,A5) -> 94 | C5: =ROUND(AVERAGEIF(Clean_Data!$Y$2:$Y$1001,A5,Clean_Data!$M$2:$M$1001),0) -> 75282
A6: Apr | B6: =COUNTIF(Clean_Data!$Y$2:$Y$1001,A6) -> 89 | C6: =ROUND(AVERAGEIF(Clean_Data!$Y$2:$Y$1001,A6,Clean_Data!$M$2:$M$1001),0) -> 77413
A7: May | B7: =COUNTIF(Clean_Data!$Y$2:$Y$1001,A7) -> 85 | C7: =ROUND(AVERAGEIF(Clean_Data!$Y$2:$Y$1001,A7,Clean_Data!$M$2:$M$1001),0) -> 80093
A8: Jun | B8: =COUNTIF(Clean_Data!$Y$2:$Y$1001,A8) -> 79 | C8: =ROUND(AVERAGEIF(Clean_Data!$Y$2:$Y$1001,A8,Clean_Data!$M$2:$M$1001),0) -> 78181
A9: Jul | B9: =COUNTIF(Clean_Data!$Y$2:$Y$1001,A9) -> 80 | C9: =ROUND(AVERAGEIF(Clean_Data!$Y$2:$Y$1001,A9,Clean_Data!$M$2:$M$1001),0) -> 78719
A10: Aug | B10: =COUNTIF(Clean_Data!$Y$2:$Y$1001,A10) -> 79 | C10: =ROUND(AVERAGEIF(Clean_Data!$Y$2:$Y$1001,A10,Clean_Data!$M$2:$M$1001),0) -> 81220
A11: Sep | B11: =COUNTIF(Clean_Data!$Y$2:$Y$1001,A11) -> 67 | C11: =ROUND(AVERAGEIF(Clean_Data!$Y$2:$Y$1001,A11,Clean_Data!$M$2:$M$1001),0) -> 82306
A12: Oct | B12: =COUNTIF(Clean_Data!$Y$2:$Y$1001,A12) -> 92 | C12: =ROUND(AVERAGEIF(Clean_Data!$Y$2:$Y$1001,A12,Clean_Data!$M$2:$M$1001),0) -> 85943
A13: Nov | B13: =COUNTIF(Clean_Data!$Y$2:$Y$1001,A13) -> 86 | C13: =ROUND(AVERAGEIF(Clean_Data!$Y$2:$Y$1001,A13,Clean_Data!$M$2:$M$1001),0) -> 83859
A14: Dec | B14: =COUNTIF(Clean_Data!$Y$2:$Y$1001,A14) -> 82 | C14: =ROUND(AVERAGEIF(Clean_Data!$Y$2:$Y$1001,A14,Clean_Data!$M$2:$M$1001),0) -> 72295
A16: B. DEPARTMENT x DESIGNATION TITLE HEADCOUNT
A17: Department | B17: Designation Title | C17: Headcount
A18: Engineering | B18: Engineering Manager | C18: =COUNTIFS(Clean_Data!$H$2:$H$1001,A18,Clean_Data!$J$2:$J$1001,B18) -> 53
A19: Engineering | B19: QA Engineer | C19: =COUNTIFS(Clean_Data!$H$2:$H$1001,A19,Clean_Data!$J$2:$J$1001,B19) -> 54
A20: Engineering | B20: Senior Software Engineer | C20: =COUNTIFS(Clean_Data!$H$2:$H$1001,A20,Clean_Data!$J$2:$J$1001,B20) -> 64
A21: Engineering | B21: Software Engineer | C21: =COUNTIFS(Clean_Data!$H$2:$H$1001,A21,Clean_Data!$J$2:$J$1001,B21) -> 64
A22: Engineering | B22: Tech Lead | C22: =COUNTIFS(Clean_Data!$H$2:$H$1001,A22,Clean_Data!$J$2:$J$1001,B22) -> 59
A23: Finance | B23: Accounts Manager | C23: =COUNTIFS(Clean_Data!$H$2:$H$1001,A23,Clean_Data!$J$2:$J$1001,B23) -> 27
A24: Finance | B24: CFO Office | C24: =COUNTIFS(Clean_Data!$H$2:$H$1001,A24,Clean_Data!$J$2:$J$1001,B24) -> 27
A25: Finance | B25: Finance Controller | C25: =COUNTIFS(Clean_Data!$H$2:$H$1001,A25,Clean_Data!$J$2:$J$1001,B25) -> 33
A26: Finance | B26: Finance Executive | C26: =COUNTIFS(Clean_Data!$H$2:$H$1001,A26,Clean_Data!$J$2:$J$1001,B26) -> 25
A27: Finance | B27: Financial Analyst | C27: =COUNTIFS(Clean_Data!$H$2:$H$1001,A27,Clean_Data!$J$2:$J$1001,B27) -> 36
A28: HR | B28: HR Director | C28: =COUNTIFS(Clean_Data!$H$2:$H$1001,A28,Clean_Data!$J$2:$J$1001,B28) -> 24
A29: HR | B29: HR Executive | C29: =COUNTIFS(Clean_Data!$H$2:$H$1001,A29,Clean_Data!$J$2:$J$1001,B29) -> 35
... A42: Sales | B42: Sales Executive | C42: =COUNTIFS(Clean_Data!$H$2:$H$1001,A42,Clean_Data!$J$2:$J$1001,B42) -> 52
A44: C. TOP DESIGNATION TITLE PER DEPARTMENT
A45: Department | B45: Top Designation Title | C45: Headcount
A46: Engineering | B46: =INDEX($B$18:$B$42,MATCH(1,INDEX(($A$18:$A$42=A46)*($C$18:$C$42=C46),0),0)) -> Senior Software Engineer | C46: =SUMPRODUCT(MAX(($A$18:$A$42=A46)*$C$18:$C$42)) -> 64
A47: Finance | B47: =INDEX($B$18:$B$42,MATCH(1,INDEX(($A$18:$A$42=A47)*($C$18:$C$42=C47),0),0)) -> Financial Analyst | C47: =SUMPRODUCT(MAX(($A$18:$A$42=A47)*$C$18:$C$42)) -> 36
A48: HR | B48: =INDEX($B$18:$B$42,MATCH(1,INDEX(($A$18:$A$42=A48)*($C$18:$C$42=C48),0),0)) -> HR Executive | C48: =SUMPRODUCT(MAX(($A$18:$A$42=A48)*$C$18:$C$42)) -> 35
A49: Operations | B49: =INDEX($B$18:$B$42,MATCH(1,INDEX(($A$18:$A$42=A49)*($C$18:$C$42=C49),0),0)) -> Logistics Coordinator | C49: =SUMPRODUCT(MAX(($A$18:$A$42=A49)*$C$18:$C$42)) -> 41
A50: Sales | B50: =INDEX($B$18:$B$42,MATCH(1,INDEX(($A$18:$A$42=A50)*($C$18:$C$42=C50),0),0)) -> Key Account Manager | C50: =SUMPRODUCT(MAX(($A$18:$A$42=A50)*$C$18:$C$42)) -> 58

Sheet Charts

Sheet Insights
B1: KEY INSIGHTS
B3: 1. Overall attrition sits at 17.6% (176 of 1,000 employees) — this is the baseline every department is measured against below.
B5: 2. Engineering (294) and Sales (272) are by far the largest departments, together making up more than half the workforce — so even a small % shift in either one moves the company-wide number a lot.
B7: 3. Attrition isn't evenly spread — some departments run noticeably above the 17.6% company average, which is where retention effort should be focused first, not spread evenly everywhere.
B9: 4. Comparing attrited vs. retained employees on rating, leaves taken, and overtime shows attrition isn't just a pay story — behavioural signals (overtime load, leave patterns) explain part of it too.
B11: 5. Gender pay comparison was run at the same rating level to check whether any gap is a genuine structural gap or just a mix effect from role/seniority distribution.
B13: 6. The 6-10 and 11-20 year experience bands carry the most headcount — the workforce is more experienced than entry-level, which should shape how the org plans senior-role succession.
B15: 7. Manager-wise team size ranking flags which managers are running the largest teams — useful context before drawing conclusions about any one manager's attrition or rating numbers.

Sheet Dashboard_design
A1: Dashboard planning notes (rough — before final build):
A3: - Top band: 5 KPI cards. Keep it to headline numbers only — total headcount, attrition rate, avg CTC, avg rating, avg experience. Anything more and it stops being scannable.
A4: - Add ONE filter, not five. Department dropdown is the most useful cut for this dataset — everything else (state, gender, education) can live in the Pivot tab for someone who wants to dig in.
A5: - Chart picks: bar for headcount (easy comparison), line for the hiring trend (time-series = line, always), doughnut for employment type (only 3 categories, doughnut reads fine at that count), bar again for attrition rate but horizontal — department names are long, horizontal bars keep labels readable.
A6: - Color idea: move away from the typical blue-corporate look. Charcoal + teal + gold + coral reads more 'analyst built this' than default Excel blue.
A7: - Native Excel slicers need a real PivotTable object underneath — built this as a dropdown + SUMIFS/COUNTIFS version instead so it still works as a single self-contained file.
A8: - Left for later: a proper predictive attrition model (logistic regression) — this version is descriptive only.

Sheet README
B1: HR WORKFORCE ANALYTICS — README
B3: What this workbook is:
B4: An end-to-end HR analytics build on a 1,000-employee dataset — the same data used in the SQL (MySQL), Python (Jupyter), Power BI and Tableau versions of this project.
B6: Sheet guide:
B7: Raw_Data — original 1,000-row dataset, untouched.
B8: Clean_Data — same data plus computed helper columns (Age_Group, Experience_Band, Join_Month, Join_Year, Attrition_Flag) used by every formula in this workbook.
B9: KPI — headline numbers (headcount, attrition rate, avg salary/CTC/rating/experience).
B10: Pivot — 11 breakdown tables: department, state, designation level, employment type, gender pay, attrition by department, education, age group, experience band, attrited vs retained, manager ranking.
B11: Calculation — monthly hiring trend and the helper matrix behind 'top designation title per department'.
B12: Charts — 6 standalone charts, larger versions of what's on the Dashboard.
B13: Dashboard — single-page view: KPI cards, a department filter (dropdown-driven, since native slicers need a real PivotTable object), and 4 key charts.
B14: Dashboard_design — rough planning notes from before the final build (kept intentionally, not polished).
... B18: A true Excel Slicer only attaches to a native PivotTable. This workbook uses formula-driven summary tables instead (so it stays one self-contained file), so the Department filter on the Dashboard is a data-validation dropdown wired to SUMIFS/COUNTIFS — same filtering experience, different mechanism under the hood.
